Based on my analysis of the codebase, I can now evaluate the hypothesis about whether the `set_selected_root_cause` method in the `event_manager.py` file could cause server crashes if the payload is invalid.

## Analysis of the Potential Bug

The hypothesis suggested that the `set_selected_root_cause` method could raise a `ValueError` if the payload is invalid, potentially crashing the server. Let's look at the key evidence:

1. In `event_manager.py`, the `set_selected_root_cause` method does indeed raise a `ValueError` with the message "Invalid root cause update payload" if both `payload.custom_root_cause` and `payload.cause_id` are `None`:

```python
def set_selected_root_cause(self, payload: AutofixRootCauseUpdatePayload):
    root_cause_selection: CustomRootCauseSelection | CodeContextRootCauseSelection | None = None
    if payload.custom_root_cause:
        root_cause_selection = CustomRootCauseSelection(
            custom_root_cause=payload.custom_root_cause,
        )
    elif payload.cause_id is not None:
        root_cause_selection = CodeContextRootCauseSelection(
            cause_id=payload.cause_id,
            instruction=payload.instruction,
        )

    if root_cause_selection is None:
        raise ValueError("Invalid root cause update payload")
```

2. Looking at the changes in `root_cause_step.py`, the new code automatically calls this method:

```python
self.context.event_manager.set_selected_root_cause(
    AutofixRootCauseUpdatePayload(
        cause_id=root_cause_output.causes[0].id,
    )
)
```

3. The code above does access `root_cause_output.causes[0].id` without checking if the array is empty, which could be a separate issue.

4. However, searching for try/catch blocks around `event_manager.set_selected_root_cause` shows that in `tasks.py`, there is indeed error handling:

```python
try:
    event_manager.set_selected_root_cause(payload)
    cur = state.get()
    # Process has no further work.
    if cur.status in AutofixStatus.terminal():
        logger.warning(f"Ignoring job, state {cur.status}")
        return
    # ...
except InitializationError as e:
    sentry_sdk.capture_exception(e)
    raise e
```

## Key Findings

1. The `set_selected_root_cause` method does throw a `ValueError` if the payload is invalid (both `custom_root_cause` and `cause_id` are None).

2. In `tasks.py`, there is a try/except block that catches `InitializationError`, but not `ValueError`. If a `ValueError` is raised by `set_selected_root_cause`, it would not be caught by this block and could propagate up.

3. In the modified `root_cause_step.py`, there is no try/except block around the call to `set_selected_root_cause`, so a `ValueError` would propagate.

## Conclusion

There is indeed a potential bug here. The `set_selected_root_cause` method can raise a `ValueError` if the payload is invalid, and this exception is not explicitly caught in all places where the method is called.

However, it's important to understand the Celery context here:

1. In `tasks.py`, the method runs inside a Celery task. Uncaught exceptions in Celery tasks typically don't crash the server, but would mark the task as failed.

2. In `root_cause_step.py`, the new code added by the changes is part of a pipeline step, and uncaught exceptions would likely be handled by the pipeline's exception handling.

It's still a bug that should be fixed since it could lead to task failures, but it's unlikely to crash the entire server unless there's a specific way the exception propagates out of the task context.

The recommended fix would be to either:
1. Add explicit error handling around the `set_selected_root_cause` call in `root_cause_step.py`
2. Modify `set_selected_root_cause` to handle invalid payloads more gracefully

This kind of bug would typically be categorized as a robustness issue rather than a critical server crash bug, unless there's additional context about how the error propagates through the system.
