Let me analyze the potential bug with the assumption that `root_cause_output.causes` could be empty when it's accessed directly at `root_cause_output.causes[0].id`.

Based on my investigation of the codebase, here's what I found:

## The Potential Bug

In `root_cause_step.py`, there's new code that automatically starts a solution step after the root cause analysis:

```python
self.context.event_manager.set_selected_root_cause(
    AutofixRootCauseUpdatePayload(
        cause_id=root_cause_output.causes[0].id,
    )
)
```

This code directly accesses `root_cause_output.causes[0]` without first checking if `causes` is empty, which could lead to an `IndexError` if `causes` is an empty list.

## Evidence Supporting This Bug

1. The `RootCauseAnalysisOutput` class in `models.py` defines `causes` as a list of `RootCauseAnalysisItem`. There's no guarantee that this list will always contain at least one item.

2. In `event_manager.py`, the `send_root_cause_analysis_result` method explicitly checks for empty causes:
   ```python
   if root_cause_output.causes:
       root_cause_step.status = AutofixStatus.COMPLETED
       root_cause_step.causes = root_cause_output.causes
       cur.status = AutofixStatus.COMPLETED
   else:
       root_cause_step.status = AutofixStatus.ERROR
       cur.status = AutofixStatus.ERROR
       root_cause_step.termination_reason = root_cause_output.termination_reason
   ```

3. Earlier in the same `_invoke` method, there's also an explicit check for empty causes:
   ```python
   self.context.event_manager.add_log(
       "Here is Autofix's proposed root cause."
       if root_cause_output.termination_reason is None and root_cause_output.causes
       else "Autofix couldn't find the root cause. Maybe help Autofix rethink by editing a card above?"
   )
   ```

4. In the PR comment section, there's another check:
   ```python
   causes = root_cause_output.causes
   cause_string = "Autofix couldn't find a root cause for this issue."
   if causes:
       cause_string = causes[0].to_markdown_string()
   ```

These checks indicate that the codebase is designed to handle cases where `root_cause_output.causes` could be empty.

## Execution Flow Analysis

Looking at the execution flow:

1. The method calls `event_manager.send_root_cause_analysis_result(root_cause_output)`, which handles the empty causes case.
2. It then adds a log about the proposed root cause, with specific messaging if causes are empty.
3. It potentially comments on a PR, with handling for empty causes.
4. Finally, it tries to set a selected root cause and start the solution step, *without* checking if causes is empty.

## Confirmation of the Bug

The unguarded access to `root_cause_output.causes[0].id` will throw an `IndexError` if `causes` is empty. The surrounding code strongly suggests that empty causes are an expected condition that needs to be handled, but the new code addition doesn't include this check.

The test file (`test_root_cause_step.py`) doesn't appear to test the case where `root_cause_output.causes` is empty, so there's no test that would catch this issue.

## Conclusion

This is a real bug that could cause the server to crash. When the root cause analysis doesn't find any causes (which appears to be a handled condition elsewhere in the code), the new code that automatically starts the solution step will try to access the first item in an empty list, leading to an `IndexError` exception.

The code should check if `root_cause_output.causes` is not empty before trying to access `causes[0]`, similar to the other checks in the same file. This would prevent the server from crashing when no root causes are found.
