Based on my thorough investigation of the getsentry/seer repository code, here's my analysis of the potential bug in the new `get_example_commit_titles` method:

# Analysis of Unhandled Exception Risks in `get_example_commit_titles`

## Summary

After careful examination, I can confirm that the method `get_example_commit_titles` lacks explicit error handling for potential exceptions from the GitHub API call to `self.repo.get_commits()`. This creates a risk of unhandled exceptions that could crash the application when this method is called.

## GitHub API Call Without Exception Handling

Looking at the implementation in `repo_client.py` (lines 457-465):

```python
@functools.lru_cache(maxsize=16)
def get_example_commit_titles(self, max_commits: int = 5) -> list[str]:
    commits = self.repo.get_commits(sha=self.base_commit_sha)
    commit_list = list(commits[:max_commits])
    commit_titles = [
        commit.commit.message.split("\n")[0] for commit in commit_list
    ]  # remove body
    return [commit.split("(#")[0].strip() for commit in commit_titles]  # remove PR number
```

There is no `try-except` block to handle potential exceptions from the GitHub API calls.

## Potential Exceptions From `get_commits`

According to the PyGithub documentation and standard practices, calls to GitHub API methods like `get_commits()` can raise various exceptions:

1. `GithubException` for various API errors (invalid parameters, permission issues)
2. `UnknownObjectException` for 404 errors (e.g., if the commit SHA doesn't exist)
3. `RateLimitExceededException` when API limits are reached
4. Network-related exceptions for connectivity issues

## Usage in Production Code

The method is called in production code in `change_describer_step.py` without any surrounding try-except block:

```python
repo_client = self.context.get_repo_client(
    repo_external_id=codebase_state.repo_external_id
)
previous_commits = repo_client.get_example_commit_titles()
```

## Error Handling Patterns Elsewhere in the Codebase

The codebase shows a consistent pattern of wrapping GitHub API calls with exception handling in other methods:

1. In `get_file_content`, errors are caught and logged:
```python
try:
    contents = self.repo.get_contents(path, ref=sha)
    # ...
except Exception as e:
    logger.exception(f"Error getting file contents: {e}")
    return None, "utf-8"
```

2. Similar exception handling patterns are found throughout the codebase for other GitHub API interactions.

## Risk Assessment

This is a genuine bug with potentially serious consequences:

1. **Crashability**: An unhandled exception here would crash the `AutofixChangeDescriberStep` process
2. **Frequency**: This method is called in the critical path of the change description workflow
3. **Severity**: Since the exception is not handled at the call site either, it would lead to a complete failure of the autofix pipeline step

## Test Coverage

The unit tests for this method (in `test_repo_client.py:test_get_example_commit_titles`) only test the happy path with mocked GitHub responses. They don't verify exception handling behavior.

## Conclusion

This is a valid bug that could cause application crashes in production. The code should follow the pattern used in other methods within the codebase by adding appropriate exception handling around the GitHub API calls in the `get_example_commit_titles` method.
