Based on my analysis of the codebase, I can now evaluate the hypothesis about whether the `set_selected_root_cause` method in the `event_manager.py` file could cause server crashes if the payload is invalid.

## Analysis of the Potential Bug

The hypothesis suggested that the `set_selected_root_cause` method could raise a `ValueError` if the payload is invalid, potentially crashing the server. Let's look at the key evidence:

1. In `event_manager.py`, the `set_selected_root_cause` method does indeed raise a `ValueError` with the message "Invalid root cause update payload" if both `payload.custom_root_cause` and `payload.cause_id` are `None`:

```python
def set_selected_root_cause(self, payload: AutofixRootCauseUpdatePayload):
    root_cause_selection: CustomRootCauseSelection | CodeContextRootCauseSelection | None = None
    if payload.custom_root_cause:
        root_cause_selection = CustomRootCauseSelection(
            custom_root_cause=payload.custom_root_cause,
        )
    elif payload.cause_id is not None:
        root_cause_selection = CodeContextRootCauseSelection(
            cause_id=payload.cause_id,
            instruction=payload.instruction,
        )

    if root_cause_selection is None:
        raise ValueError("Invalid root cause update payload")
```

2. Looking at the changes in `root_cause_step.py`, the new code automatically calls this method:

```python
self.context.event_manager.set_selected_root_cause(
    AutofixRootCauseUpdatePayload(
        cause_id=root_cause_output.causes[0].id,
    )
)
```

3. The code above does access `root_cause_output.causes[0].id` without checking if the array is empty, which could be a separate issue.

4. However, searching for try/catch blocks around `event_manager.set_selected_root_cause` shows that in `tasks.py`, there is indeed error handling:

```python
try:
    event_manager.set_selected_root_cause(payload)
    cur = state.get()
    # Process has no further work.
    if cur.status in AutofixStatus.terminal():
        logger.warning(f"Ignoring job, state {cur.status}")
        return
    # ...
except InitializationError as e:
    sentry_sdk.capture_exception(e)
    raise e
```

## Key Findings

1. The `set_selected_root_cause` method does throw a `ValueError` if the payload is invalid (both `custom_root_cause` and `cause_id` are None).

2. In `tasks.py`, there is a try/except block that catches `InitializationError`, but not `ValueError`. If a `ValueError` is raised by `set_selected_root_cause`, it would not be caught by this block and could propagate up.

3. In the modified `root_cause_step.py`, there is no try/except block around the call to `set_selected_root_cause`, so a `ValueError` would propagate.

## Conclusion

There is indeed a potential bug here. The `set_selected_root_cause` method can raise a `ValueError` if the payload is invalid, and this exception is not explicitly caught in all places where the method is called.

However, it's important to understand the Celery context here:

1. In `tasks.py`, the method runs inside a Celery task. Uncaught exceptions in Celery tasks typically don't crash the server, but would mark the task as failed.

2. In `root_cause_step.py`, the new code added by the changes is part of a pipeline step, and uncaught exceptions would likely be handled by the pipeline's exception handling.

It's still a bug that should be fixed since it could lead to task failures, but it's unlikely to crash the entire server unless there's a specific way the exception propagates out of the task context.

The recommended fix would be to either:
1. Add explicit error handling around the `set_selected_root_cause` call in `root_cause_step.py`
2. Modify `set_selected_root_cause` to handle invalid payloads more gracefully

This kind of bug would typically be categorized as a robustness issue rather than a critical server crash bug, unless there's additional context about how the error propagates through the system.

----------------------------------------------------------------------------------------------------
Based on my investigation into the code related to `self.step_request_fields` in the `root_cause_step.py` file, here's my analysis of the potential bug:

## Analysis of `step_request_fields` and `AutofixSolutionStepRequest`

When reviewing the updated code in `root_cause_step.py`, I found that the function attempts to create a new solution step with:

```python
self.next(
    AutofixSolutionStep.get_signature(
        AutofixSolutionStepRequest(
            **self.step_request_fields,
            initial_memory=[],
        ),
    ),
    queue=app_config.CELERY_WORKER_QUEUE,
)
```

Let's analyze what happens here:

1. `self.step_request_fields` comes from the `PipelineStep` class in `pipeline.py` and is defined as:
   ```python
   @property
   def step_request_fields(self):
       return make_step_request_fields(self.context)
   ```

2. The `make_step_request_fields` function in `pipeline.py` returns:
   ```python
   def make_step_request_fields(context: PipelineContext):
       return {"run_id": context.run_id}
   ```

3. The `AutofixSolutionStepRequest` class requires the following fields:
   ```python
   class AutofixSolutionStepRequest(PipelineStepTaskRequest):
       initial_memory: list[Message] = []
   ```

4. And `PipelineStepTaskRequest` (parent class) requires:
   ```python
   class PipelineStepTaskRequest(BaseModel):
       run_id: int
       step_id: int = Field(default_factory=lambda: uuid.uuid4().int)
   ```

## Conclusion

There is **no bug** with this approach for the following reasons:

1. The `step_request_fields` dictionary only contains `run_id`, which is required by `PipelineStepTaskRequest`, the parent class of `AutofixSolutionStepRequest`.

2. The `PipelineStepTaskRequest` has a default value for `step_id` which will be automatically generated if not provided.

3. The `AutofixSolutionStepRequest` already has a default empty list for `initial_memory`, but the code is explicitly setting it to an empty list anyway.

All required fields are properly accounted for:
- `run_id` is provided via `self.step_request_fields`
- `step_id` has a default value in the parent class
- `initial_memory` is explicitly provided

The pattern of using `**self.step_request_fields` to pass common fields to step requests is used in multiple places in the codebase and appears to be a standard pattern. This is expected behavior and not a bug that would cause server crashes.
----------------------------------------------------------------------------------------------------

Based on my investigation, I can now provide a clear assessment of the potential bug hypothesis:

# Analysis of the Potential Bug: Missing `CELERY_WORKER_QUEUE` Attribute

## Conclusion

The hypothesis that `app_config.CELERY_WORKER_QUEUE` might not be defined and could lead to an `AttributeError` is **not a valid concern**. There is strong evidence that this attribute is properly defined and has adequate fallback mechanisms.

## Evidence

1. In `src/seer/configuration.py`, the `AppConfig` class explicitly defines `CELERY_WORKER_QUEUE` with a default value:
   ```python
   CELERY_WORKER_QUEUE: str = "seer"
   ```

2. The `AppConfig` class includes a validation method that specifically warns when this value is not set in production:
   ```python
   if not self.CELERY_WORKER_QUEUE:
       logger.warning('CELERY_WORKER_QUEUE is not set in production! Will default to "seer"')
   ```
   This shows the developers intentionally set a default value and have handling for cases when it's not explicitly configured.

3. The attribute is used consistently throughout the codebase, as evidenced by the grep search results showing multiple places where `app_config.CELERY_WORKER_QUEUE` is referenced in various task scheduling logic.

4. In `src/celery_app/config.py`, the Celery configuration is set up to use this value as the default queue, further confirming that it's a central configuration parameter that the system is designed to use.

## Why This Won't Crash the Server

Even in the unlikely scenario where the value isn't set in the environment:

1. The class provides a default value of "seer"
2. There's explicit logging to warn about the missing value in production
3. There's a comment indicating this is expected behavior: `Will default to "seer"`

This demonstrates that the system is designed to handle the case where this value isn't explicitly configured, making it extremely unlikely to cause a server crash.

## Final Assessment

The use of `app_config.CELERY_WORKER_QUEUE` in the code change is safe and follows established patterns in the codebase. The property is defined with a default value, has validation, and is regularly used throughout the codebase in a similar manner to the implementation in the changed code.

This is not a bug that would cause the server to crash unexpectedly.

----------------------------------------------------------------------------------------------------

Let me analyze the potential bug with the assumption that `root_cause_output.causes` could be empty when it's accessed directly at `root_cause_output.causes[0].id`.

Based on my investigation of the codebase, here's what I found:

## The Potential Bug

In `root_cause_step.py`, there's new code that automatically starts a solution step after the root cause analysis:

```python
self.context.event_manager.set_selected_root_cause(
    AutofixRootCauseUpdatePayload(
        cause_id=root_cause_output.causes[0].id,
    )
)
```

This code directly accesses `root_cause_output.causes[0]` without first checking if `causes` is empty, which could lead to an `IndexError` if `causes` is an empty list.

## Evidence Supporting This Bug

1. The `RootCauseAnalysisOutput` class in `models.py` defines `causes` as a list of `RootCauseAnalysisItem`. There's no guarantee that this list will always contain at least one item.

2. In `event_manager.py`, the `send_root_cause_analysis_result` method explicitly checks for empty causes:
   ```python
   if root_cause_output.causes:
       root_cause_step.status = AutofixStatus.COMPLETED
       root_cause_step.causes = root_cause_output.causes
       cur.status = AutofixStatus.COMPLETED
   else:
       root_cause_step.status = AutofixStatus.ERROR
       cur.status = AutofixStatus.ERROR
       root_cause_step.termination_reason = root_cause_output.termination_reason
   ```

3. Earlier in the same `_invoke` method, there's also an explicit check for empty causes:
   ```python
   self.context.event_manager.add_log(
       "Here is Autofix's proposed root cause."
       if root_cause_output.termination_reason is None and root_cause_output.causes
       else "Autofix couldn't find the root cause. Maybe help Autofix rethink by editing a card above?"
   )
   ```

4. In the PR comment section, there's another check:
   ```python
   causes = root_cause_output.causes
   cause_string = "Autofix couldn't find a root cause for this issue."
   if causes:
       cause_string = causes[0].to_markdown_string()
   ```

These checks indicate that the codebase is designed to handle cases where `root_cause_output.causes` could be empty.

## Execution Flow Analysis

Looking at the execution flow:

1. The method calls `event_manager.send_root_cause_analysis_result(root_cause_output)`, which handles the empty causes case.
2. It then adds a log about the proposed root cause, with specific messaging if causes are empty.
3. It potentially comments on a PR, with handling for empty causes.
4. Finally, it tries to set a selected root cause and start the solution step, *without* checking if causes is empty.

## Confirmation of the Bug

The unguarded access to `root_cause_output.causes[0].id` will throw an `IndexError` if `causes` is empty. The surrounding code strongly suggests that empty causes are an expected condition that needs to be handled, but the new code addition doesn't include this check.

The test file (`test_root_cause_step.py`) doesn't appear to test the case where `root_cause_output.causes` is empty, so there's no test that would catch this issue.

## Conclusion

This is a real bug that could cause the server to crash. When the root cause analysis doesn't find any causes (which appears to be a handled condition elsewhere in the code), the new code that automatically starts the solution step will try to access the first item in an empty list, leading to an `IndexError` exception.

The code should check if `root_cause_output.causes` is not empty before trying to access `causes[0]`, similar to the other checks in the same file. This would prevent the server from crashing when no root causes are found.
