After investigating the "Last Step Agent Comment" hypothesis, I've gathered enough information to provide a conclusive analysis.

## Analysis of the Potential Bug

The PR modifies the `comment_on_thread` function to handle both user-initiated and agent-initiated comment threads. The key difference is where these threads are stored:

- User-initiated threads are stored in `step.active_comment_thread`
- Agent-initiated threads are stored in `step_after.agent_comment_thread` (the step after the current one)

The potential bug hypothesis was: "If a user tries to create or interact with an agent comment thread on the last step of a workflow, the code will likely crash since there's no 'next step' to store the agent comment thread."

## Key Evidence

Let's look at the critical code sections that handle agent comment threads:

1. When checking for the existence of the next step:
```python
step_after = (
    state.get().steps[step_index + 1] if step_index + 1 < len(state.get().steps) else None
)  # the agent comment thread is on the step after the processing step
```

2. The code explicitly checks for this edge case in multiple places:
```python
if not step_after and request.payload.is_agent_comment:
    raise ValueError("No agent-initiated comment thread found")
```
```python
if not step_after and request.payload.is_agent_comment:
    raise ValueError("No agent-initiated comment thread found")
```

3. In the `resolve_comment_thread` function:
```python
if request.payload.is_agent_comment and step_index + 1 < len(state.get().steps):
    cur.steps[step_index + 1].agent_comment_thread = None
elif request.payload.thread_id == cur.steps[step_index].active_comment_thread.id:
    cur.steps[step_index].active_comment_thread = None
else:
    raise ValueError("No matching comment thread found; unable to resolve thread")
```

## Testing Evidence

Looking at `tests/automation/autofix/test_autofix_tasks.py`, I didn't find any tests that specifically verify the behavior when dealing with agent comment threads on the last step. While there are tests for comment threads in general, I didn't see tests that target this specific edge case.

## Conclusion

This is indeed a potential bug. The code explicitly raises a `ValueError` when attempting to reference an agent comment thread on the last step, indicating that this is an unsupported operation. However, this is an intentional error (not a silent failure), and the code correctly handles this edge case by checking if `step_after` is None before trying to access it.

The error is intentional, but it could still cause user confusion if the UI allows users to attempt this operation. The error messages are clear ("No agent-initiated comment thread found"), which should help with troubleshooting.

It's worth noting that while the code has proper checks to prevent unexpected crashes (by explicitly raising ValueErrors with descriptive messages), there's no mechanism to prevent attempting this operation in the first place. Ideally, the UI would disable the option to create or interact with agent comment threads on the last step.

The bug is real in the sense that it prevents a user from performing an operation they might expect to be available, but the system handles it gracefully by raising an explicit error rather than crashing unexpectedly.

----------------------------------------------------------------------------------------------------

After thoroughly investigating the code, I'll assess the potential for bugs related to multiple resolves and race conditions in the new `resolve_comment_thread` function.

## Analysis of the Resolve Comment Thread Function

The new `resolve_comment_thread` function was added to handle resolving or removing comment threads. Here's the implementation from the diff:

```python
def resolve_comment_thread(request: AutofixUpdateRequest):
    if not isinstance(request.payload, AutofixResolveCommentThreadPayload):
        raise ValueError("Invalid payload type for resolve_comment_thread")

    state = ContinuationState(request.run_id)

    step_index = request.payload.step_index
    with state.update() as cur:
        if request.payload.is_agent_comment and step_index + 1 < len(state.get().steps):
            cur.steps[step_index + 1].agent_comment_thread = None
        elif request.payload.thread_id == cur.steps[step_index].active_comment_thread.id:
            cur.steps[step_index].active_comment_thread = None
        else:
            raise ValueError("No matching comment thread found; unable to resolve thread")
```

### Concurrency and Race Conditions

From examining the `state.update()` method in `src/seer/automation/state.py`:

```python
@contextlib.contextmanager
def update(self):
    """
    Uses a 'with for update' clause on the db run id, ensuring it is safe against concurrent transactions.
    Note however, that if you have two competing updates in which neither can fully complete (say a circle
    of inter related locks), the database may reach a deadlock state which last until the lock timeout configured
    on the postgres database.
    """
    with Session() as session:
        r = session.execute(
            select(DbRunState).where(DbRunState.id == self.id).with_for_update()
        ).scalar_one_or_none()
        self.validate(r)
        assert r
        value = self.model.model_validate(r.value)
        yield value
        self.before_update(value)
        db_state = DbRunState(id=self.id, value=value.model_dump(mode="json"))
        self.apply_to_run_state(value, db_state)
        session.merge(db_state)
        session.commit()
```

The function uses SQL's `with_for_update` to lock the database row, which protects against concurrent modifications of the same record.

### Potential Null Reference Bug

The original hypothesis about multiple resolves causing crashes appears to be valid. In the `resolve_comment_thread` function:

```python
elif request.payload.thread_id == cur.steps[step_index].active_comment_thread.id:
    cur.steps[step_index].active_comment_thread = None
```

There's no check to verify that `active_comment_thread` is not None before accessing its `.id` property. If the thread has already been resolved (set to None) by another request, this would cause a NullPointerException (AttributeError in Python).

### Test Evidence

Looking at the tests in `tests/automation/autofix/test_autofix_tasks.py`, there are tests for resolving comment threads, but nothing specifically testing the case of resolving an already-resolved thread:

```python
def test_resolve_comment_thread():
    # Create initial state with a step that has an existing thread
    state = next(generate(AutofixContinuation))
    step = DefaultStep(
        title="Test Step",
        status=AutofixStatus.COMPLETED,
        active_comment_thread=CommentThread(
            id="existing_thread",
            selected_text="Test selection",
            messages=[
                Message(role="user", content="Test comment"),
                Message(role="assistant", content="Test response"),
            ],
        ),
    )
    state.steps = [step]

    with Session() as session:
        session.add(DbRunState(id=1, group_id=100, value=state.model_dump(mode="json")))
        session.commit()

    request = AutofixUpdateRequest(
        run_id=1,
        payload=AutofixResolveCommentThreadPayload(
            type=AutofixUpdateType.RESOLVE_COMMENT_THREAD,
            thread_id="existing_thread",
            step_index=0,
            is_agent_comment=False,
        ),
    )

    resolve_comment_thread(request)

    # Verify thread was removed
    updated_state = get_autofix_state(run_id=1)
    assert updated_state is not None
    updated_step = updated_state.get().steps[0]
    assert updated_step.active_comment_thread is None
```

## Conclusion

Based on the code analysis, I've identified a confirmed potential bug that could cause the server to crash:

**Bug**: There's a missing null check in the `resolve_comment_thread` function. If `active_comment_thread` is already `None` (perhaps due to a previous resolve operation) and the function tries to access `.id` on it, this will cause an AttributeError (Python's version of a NullPointerException).

This is a significant bug that could cause the server to unexpectedly crash if:
1. Multiple users or requests try to resolve the same thread at nearly the same time
2. A user tries to resolve a thread that has already been resolved
3. A frontend issue causes multiple identical resolve requests to be sent

While database transaction locks would prevent most race conditions, they wouldn't prevent this particular issue where a second request comes in after the first one has already completed successfully.

This bug should be fixed by adding a null check before accessing the `active_comment_thread.id` property:

```python
elif cur.steps[step_index].active_comment_thread and request.payload.thread_id == cur.steps[step_index].active_comment_thread.id:
    cur.steps[step_index].active_comment_thread = None
```

----------------------------------------------------------------------------------------------------

Based on my investigation, I need to evaluate whether there's a real bug in the code changes that could cause an `IndexError` or `AttributeError` when handling agent comment threads. Let me analyze the relevant code sections carefully.

## Analysis of Agent Comment Thread Handling

In the changed code, I examined how the `step_after` variable is handled, which could potentially lead to an IndexError if accessed improperly. The code adds support for "agent-initiated comment threads" which are stored in the next step after the current processing step.

Looking at all places where `step_after` and `agent_comment_thread` are accessed:

1. The code properly checks `if not step_after or not step_after.agent_comment_thread` before raising an error at line 734-735.

2. Before accessing `step_after.agent_comment_thread.messages`, the code properly checks with `if step_after and step_after.agent_comment_thread else []` at lines 776-780.

3. Similar null checks exist for the `selected_text` access at lines 786-788.

4. At line 766-767, the code also does a proper null check: `if not step_after and request.payload.is_agent_comment` before raising an error.

5. I examined the `resolve_comment_thread` function, and it has correct null checks at lines 858-863 before accessing thread properties.

I also reviewed the `CommentThread` class definition in `models.py` and found that it is properly defined with nullable fields and default values for lists.

From the test file `test_autofix_tasks.py`, I can see that there are tests specifically for handling agent comment threads, including tests for resolving them.

## Conclusion

After thorough investigation, I don't see evidence that a real IndexError or AttributeError bug exists in the handling of agent comment threads. The code appears to have proper null checks in all places where `step_after` or `step_after.agent_comment_thread` might be accessed.

Specifically:
1. The code correctly checks for `step_after` being null before accessing it
2. When accessing properties like `messages` or `selected_text`, the code provides appropriate fallbacks
3. When needing to raise errors for invalid states, the code does proper validation first
4. The `resolve_comment_thread` function appropriately handles both user and agent comment threads

While the changes are complex and involve manipulating indexes and accessing properties that could be null, the authors have included appropriate validation to prevent crashes. The test file also includes tests for these code paths, which suggests they've been tested.

Therefore, the initial hypothesis about missing null checks causing an IndexError or AttributeError does not appear to be a real threat to the system.

----------------------------------------------------------------------------------------------------

Based on my investigation, let me evaluate the potential bug related to the null reference in the `resolve_comment_thread` function:

```python
def resolve_comment_thread(request: AutofixUpdateRequest):
    if not isinstance(request.payload, AutofixResolveCommentThreadPayload):
        raise ValueError("Invalid payload type for resolve_comment_thread")

    state = ContinuationState(request.run_id)

    step_index = request.payload.step_index
    with state.update() as cur:
        if request.payload.is_agent_comment and step_index + 1 < len(state.get().steps):
            cur.steps[step_index + 1].agent_comment_thread = None
        elif request.payload.thread_id == cur.steps[step_index].active_comment_thread.id:
            cur.steps[step_index].active_comment_thread = None
        else:
            raise ValueError("No matching comment thread found; unable to resolve thread")
```

## Analysis of the Potential Bug

There is indeed a potential bug in the `resolve_comment_thread` function. The code attempts to access `cur.steps[step_index].active_comment_thread.id` without first checking if `active_comment_thread` is None. If `active_comment_thread` is None, this will trigger an AttributeError when trying to access `.id`.

Let's look at the related model definitions from `models.py`:

```python
class BaseStep(BaseModel):
    # ...
    active_comment_thread: CommentThread | None = None  # user-initiated comment thread
    agent_comment_thread: CommentThread | None = None  # Autofix-initiated comment thread
    # ...
```

The model definition clearly shows that `active_comment_thread` is defined as optional (`CommentThread | None = None`), confirming that it can be None.

## Scenarios that Could Trigger the Bug

This bug could potentially happen in the following scenarios:

1. If a comment thread was already resolved (set to None) and another attempt is made to resolve it
2. If there was a race condition where one user resolves a thread while another is trying to do the same
3. If the frontend sends an incorrect thread ID or requests to resolve a non-existent thread

## Verification

The bug is a real threat because:

1. The code explicitly expects `active_comment_thread` to be None in some cases (it's set to None in multiple places in the code)
2. There's no null check before accessing `.id`
3. The code in `comment_on_thread` contains proper null checks before accessing `active_comment_thread`, suggesting that it's expected to be None in some cases

## Impact

If triggered, this bug would cause an AttributeError, which would crash the request handling and might result in an error response to the client. The server itself would likely continue running, but the specific request would fail with a 500 internal server error.

## Conclusion

The issue is a real bug that could cause a runtime error (AttributeError) when a user attempts to resolve a thread that has already been resolved or doesn't exist. The code should be modified to check if `active_comment_thread` is None before attempting to access its `id` property.

A proper fix would be to change:

```python
elif request.payload.thread_id == cur.steps[step_index].active_comment_thread.id:
```

to:

```python
elif cur.steps[step_index].active_comment_thread and request.payload.thread_id == cur.steps[step_index].active_comment_thread.id:
```

This is a classic null reference bug that could definitely happen in production and would cause an unexpected server-side exception.

----------------------------------------------------------------------------------------------------

Now I can see that the `AutofixResolveCommentThreadPayload` class is indeed properly defined in the `src/seer/automation/autofix/models.py` file. I can see it in the file at lines 483-487:

```python
class AutofixResolveCommentThreadPayload(BaseModel):
    type: Literal[AutofixUpdateType.RESOLVE_COMMENT_THREAD]
    thread_id: str
    step_index: int
    is_agent_comment: bool = False
```

This class is also properly included in the Union type for the `payload` field in the `AutofixUpdateRequest` class:

```python
class AutofixUpdateRequest(BaseModel):
    run_id: int
    payload: Union[
        AutofixRootCauseUpdatePayload,
        AutofixSolutionUpdatePayload,
        AutofixCreatePrUpdatePayload,
        AutofixCreateBranchUpdatePayload,
        AutofixUserMessagePayload,
        AutofixRestartFromPointPayload,
        AutofixUpdateCodeChangePayload,
        AutofixCommentThreadPayload,
        AutofixResolveCommentThreadPayload,
    ] = Field(discriminator="type")
```

Let me also check if the `AutofixUpdateType` enum includes the `RESOLVE_COMMENT_THREAD` value to ensure everything is properly defined:

```python
class AutofixUpdateType(str, enum.Enum):
    SELECT_ROOT_CAUSE = "select_root_cause"
    SELECT_SOLUTION = "select_solution"
    CREATE_PR = "create_pr"
    CREATE_BRANCH = "create_branch"
    USER_MESSAGE = "user_message"
    RESTART_FROM_POINT_WITH_FEEDBACK = "restart_from_point_with_feedback"
    UPDATE_CODE_CHANGE = "update_code_change"
    COMMENT_THREAD = "comment_thread"
    RESOLVE_COMMENT_THREAD = "resolve_comment_thread"
```

Yes, I can see that `RESOLVE_COMMENT_THREAD` is properly defined in the enum as well.

Based on my investigation, I can conclusively say that this potential bug is not an issue. The `AutofixResolveCommentThreadPayload` class is properly defined in the codebase, and it matches what the code in the PR expects. The PR correctly imports this class, which exists in the models.py file with all the required fields:
- `type` (set to `AutofixUpdateType.RESOLVE_COMMENT_THREAD`)
- `thread_id` (a string)
- `step_index` (an integer)
- `is_agent_comment` (a boolean, defaulting to False)

Therefore, Potential Bug 3 is not a concern for this PR.
