After investigating the potential "Bug 5: Unsafe Feature Flag Implementation" from the hypothesis, I can provide a thorough analysis:

## Investigation Summary

The code change in `src/seer/automation/autofix/tools.py` adds a feature guard with the following condition:

```python
if (
    isinstance(self.context, AutofixContext)
    and isinstance(run_request, AutofixRequest)
    and not run_request.options.disable_interactivity
    and (run_request.invoking_user and run_request.invoking_user.id == 3283725)
):  # TODO temporary guard for Rohan (@roaga) to test in prod
```

This guards access to two new features: `get_trace_event_details` and `get_profile_for_trace_event`.

## Findings

1. **The feature flag implementation is safe from crashes:**
   - The code properly checks `run_request.invoking_user` is not None before accessing `run_request.invoking_user.id`
   - This is done with the compound condition: `(run_request.invoking_user and run_request.invoking_user.id == 3283725)`
   - The `and` operator in Python short-circuits, so if `run_request.invoking_user` is `None`, it won't try to access the `id` attribute

2. **Similar pattern used consistently across the codebase:**
   - The same safe pattern is used in other files:
     - `components/root_cause/component.py`: `state.request.invoking_user and state.request.invoking_user.id == 3283725`
     - `components/solution/component.py`: `state.request.invoking_user and state.request.invoking_user.id == 3283725`

3. **`invoking_user` field is correctly handled across the system:**
   - In the `AutofixRequest` model, `invoking_user` is defined as nullable: `invoking_user: AutofixUserDetails | None = None`
   - The `_call_autofix` function in `src/sentry/seer/autofix.py` properly handles the null case: `if not isinstance(user, AnonymousUser) else None`

4. **Other accesses to `invoking_user` check for None first:**
   - In `autofix_context.py`, both accesses to `state.request.invoking_user.display_name` are guarded by `if state.request.invoking_user`
   - In `steps/steps.py`, `invoking_user` is assigned to a variable and then used, no direct property access that could crash

## Conclusion

This is **not a bug that would cause the server to crash**. The code safely checks for the existence of `run_request.invoking_user` before attempting to access its `id` attribute. The pattern `(run_request.invoking_user and run_request.invoking_user.id == 3283725)` ensures that the right-hand side is only evaluated if the left-hand side is truthy.

The hardcoded user ID (3283725) is explicitly marked as temporary with the comment: `# TODO temporary guard for Rohan (@roaga) to test in prod`. This indicates it's an intentional, temporary feature flag for testing rather than a bug.

All other accesses to the `invoking_user` field throughout the codebase properly check for its existence before accessing its properties, following the same safe pattern.
