After investigating the "Last Step Agent Comment" hypothesis, I've gathered enough information to provide a conclusive analysis.

## Analysis of the Potential Bug

The PR modifies the `comment_on_thread` function to handle both user-initiated and agent-initiated comment threads. The key difference is where these threads are stored:

- User-initiated threads are stored in `step.active_comment_thread`
- Agent-initiated threads are stored in `step_after.agent_comment_thread` (the step after the current one)

The potential bug hypothesis was: "If a user tries to create or interact with an agent comment thread on the last step of a workflow, the code will likely crash since there's no 'next step' to store the agent comment thread."

## Key Evidence

Let's look at the critical code sections that handle agent comment threads:

1. When checking for the existence of the next step:
```python
step_after = (
    state.get().steps[step_index + 1] if step_index + 1 < len(state.get().steps) else None
)  # the agent comment thread is on the step after the processing step
```

2. The code explicitly checks for this edge case in multiple places:
```python
if not step_after and request.payload.is_agent_comment:
    raise ValueError("No agent-initiated comment thread found")
```
```python
if not step_after and request.payload.is_agent_comment:
    raise ValueError("No agent-initiated comment thread found")
```

3. In the `resolve_comment_thread` function:
```python
if request.payload.is_agent_comment and step_index + 1 < len(state.get().steps):
    cur.steps[step_index + 1].agent_comment_thread = None
elif request.payload.thread_id == cur.steps[step_index].active_comment_thread.id:
    cur.steps[step_index].active_comment_thread = None
else:
    raise ValueError("No matching comment thread found; unable to resolve thread")
```

## Testing Evidence

Looking at `tests/automation/autofix/test_autofix_tasks.py`, I didn't find any tests that specifically verify the behavior when dealing with agent comment threads on the last step. While there are tests for comment threads in general, I didn't see tests that target this specific edge case.

## Conclusion

This is indeed a potential bug. The code explicitly raises a `ValueError` when attempting to reference an agent comment thread on the last step, indicating that this is an unsupported operation. However, this is an intentional error (not a silent failure), and the code correctly handles this edge case by checking if `step_after` is None before trying to access it.

The error is intentional, but it could still cause user confusion if the UI allows users to attempt this operation. The error messages are clear ("No agent-initiated comment thread found"), which should help with troubleshooting.

It's worth noting that while the code has proper checks to prevent unexpected crashes (by explicitly raising ValueErrors with descriptive messages), there's no mechanism to prevent attempting this operation in the first place. Ideally, the UI would disable the option to create or interact with agent comment threads on the last step.

The bug is real in the sense that it prevents a user from performing an operation they might expect to be available, but the system handles it gracefully by raising an explicit error rather than crashing unexpectedly.
